[2025-04-03T13:22:14.357+0000] {taskinstance.py:1159} INFO - Dependencies all met for dep_context=non-requeueable deps ti=<TaskInstance: POC_orange_data2.spark_task2 manual__2025-04-03T13:22:12.639460+00:00 [queued]>
[2025-04-03T13:22:14.393+0000] {taskinstance.py:1159} INFO - Dependencies all met for dep_context=requeueable deps ti=<TaskInstance: POC_orange_data2.spark_task2 manual__2025-04-03T13:22:12.639460+00:00 [queued]>
[2025-04-03T13:22:14.395+0000] {taskinstance.py:1361} INFO - Starting attempt 1 of 1
[2025-04-03T13:22:14.480+0000] {taskinstance.py:1382} INFO - Executing <Task(PythonOperator): spark_task2> on 2025-04-03 13:22:12.639460+00:00
[2025-04-03T13:22:14.500+0000] {standard_task_runner.py:57} INFO - Started process 216 to run task
[2025-04-03T13:22:14.514+0000] {standard_task_runner.py:84} INFO - Running: ['***', 'tasks', 'run', 'POC_orange_data2', 'spark_task2', 'manual__2025-04-03T13:22:12.639460+00:00', '--job-id', '26', '--raw', '--subdir', 'DAGS_FOLDER/pass_data.py', '--cfg-path', '/tmp/tmp72jdje9l']
[2025-04-03T13:22:14.523+0000] {standard_task_runner.py:85} INFO - Job 26: Subtask spark_task2
[2025-04-03T13:22:14.701+0000] {task_command.py:416} INFO - Running <TaskInstance: POC_orange_data2.spark_task2 manual__2025-04-03T13:22:12.639460+00:00 [running]> on host 44552ddc80b1
[2025-04-03T13:22:15.442+0000] {taskinstance.py:1662} INFO - Exporting env vars: AIRFLOW_CTX_DAG_OWNER='***' AIRFLOW_CTX_DAG_ID='POC_orange_data2' AIRFLOW_CTX_TASK_ID='spark_task2' AIRFLOW_CTX_EXECUTION_DATE='2025-04-03T13:22:12.639460+00:00' AIRFLOW_CTX_TRY_NUMBER='1' AIRFLOW_CTX_DAG_RUN_ID='manual__2025-04-03T13:22:12.639460+00:00'
[2025-04-03T13:22:32.302+0000] {logging_mixin.py:154} INFO - loading data
[2025-04-03T13:22:35.170+0000] {taskinstance.py:1937} ERROR - Task failed with exception
Traceback (most recent call last):
  File "/home/airflow/.local/lib/python3.8/site-packages/airflow/operators/python.py", line 192, in execute
    return_value = self.execute_callable()
  File "/home/airflow/.local/lib/python3.8/site-packages/airflow/operators/python.py", line 209, in execute_callable
    return self.python_callable(*self.op_args, **self.op_kwargs)
  File "/opt/airflow/dags/pass_data.py", line 16, in spark_processing
    df = spark.read.csv("/tank/csv/generated_data_*.csv", header=True, inferSchema=True, sep="|")
  File "/home/airflow/.local/lib/python3.8/site-packages/pyspark/sql/readwriter.py", line 740, in csv
    return self._df(self._jreader.csv(self._spark._sc._jvm.PythonUtils.toSeq(path)))
  File "/home/airflow/.local/lib/python3.8/site-packages/py4j/java_gateway.py", line 1322, in __call__
    return_value = get_return_value(
  File "/home/airflow/.local/lib/python3.8/site-packages/pyspark/errors/exceptions/captured.py", line 185, in deco
    raise converted from None
pyspark.errors.exceptions.captured.AnalysisException: [PATH_NOT_FOUND] Path does not exist: file:/tank/csv/generated_data_*.csv.
[2025-04-03T13:22:35.211+0000] {taskinstance.py:1400} INFO - Marking task as FAILED. dag_id=POC_orange_data2, task_id=spark_task2, execution_date=20250403T132212, start_date=20250403T132214, end_date=20250403T132235
[2025-04-03T13:22:35.237+0000] {standard_task_runner.py:104} ERROR - Failed to execute job 26 for task spark_task2 ([PATH_NOT_FOUND] Path does not exist: file:/tank/csv/generated_data_*.csv.; 216)
[2025-04-03T13:22:35.296+0000] {local_task_job_runner.py:228} INFO - Task exited with return code 1
[2025-04-03T13:22:35.330+0000] {taskinstance.py:2778} INFO - 0 downstream tasks scheduled from follow-on schedule check
