[2025-04-30T10:27:08.379+0000] {taskinstance.py:1159} INFO - Dependencies all met for dep_context=non-requeueable deps ti=<TaskInstance: POC_orange_data2.es_task manual__2025-04-30T10:26:22.209765+00:00 [queued]>
[2025-04-30T10:27:08.413+0000] {taskinstance.py:1159} INFO - Dependencies all met for dep_context=requeueable deps ti=<TaskInstance: POC_orange_data2.es_task manual__2025-04-30T10:26:22.209765+00:00 [queued]>
[2025-04-30T10:27:08.414+0000] {taskinstance.py:1361} INFO - Starting attempt 2 of 2
[2025-04-30T10:27:08.518+0000] {taskinstance.py:1382} INFO - Executing <Task(PythonOperator): es_task> on 2025-04-30 10:26:22.209765+00:00
[2025-04-30T10:27:08.538+0000] {standard_task_runner.py:57} INFO - Started process 1872 to run task
[2025-04-30T10:27:08.548+0000] {standard_task_runner.py:84} INFO - Running: ['***', 'tasks', 'run', 'POC_orange_data2', 'es_task', 'manual__2025-04-30T10:26:22.209765+00:00', '--job-id', '156', '--raw', '--subdir', 'DAGS_FOLDER/pass_data.py', '--cfg-path', '/tmp/tmpl7vcbofa']
[2025-04-30T10:27:08.556+0000] {standard_task_runner.py:85} INFO - Job 156: Subtask es_task
[2025-04-30T10:27:09.129+0000] {task_command.py:416} INFO - Running <TaskInstance: POC_orange_data2.es_task manual__2025-04-30T10:26:22.209765+00:00 [running]> on host d9ec160e05b6
[2025-04-30T10:27:09.396+0000] {taskinstance.py:1662} INFO - Exporting env vars: AIRFLOW_CTX_DAG_OWNER='***' AIRFLOW_CTX_DAG_ID='POC_orange_data2' AIRFLOW_CTX_TASK_ID='es_task' AIRFLOW_CTX_EXECUTION_DATE='2025-04-30T10:26:22.209765+00:00' AIRFLOW_CTX_TRY_NUMBER='2' AIRFLOW_CTX_DAG_RUN_ID='manual__2025-04-30T10:26:22.209765+00:00'
[2025-04-30T10:27:09.434+0000] {logging_mixin.py:154} INFO - [INFO] Connecting to Elasticsearch...
[2025-04-30T10:27:09.439+0000] {taskinstance.py:1937} ERROR - Task failed with exception
Traceback (most recent call last):
  File "/home/airflow/.local/lib/python3.8/site-packages/airflow/operators/python.py", line 192, in execute
    return_value = self.execute_callable()
  File "/home/airflow/.local/lib/python3.8/site-packages/airflow/operators/python.py", line 209, in execute_callable
    return self.python_callable(*self.op_args, **self.op_kwargs)
  File "/opt/airflow/dags/pass_data.py", line 78, in save_to_es
    for idx, doc in enumerate(data):
TypeError: 'NoneType' object is not iterable
[2025-04-30T10:27:09.462+0000] {taskinstance.py:1400} INFO - Marking task as FAILED. dag_id=POC_orange_data2, task_id=es_task, execution_date=20250430T102622, start_date=20250430T102708, end_date=20250430T102709
[2025-04-30T10:27:09.492+0000] {standard_task_runner.py:104} ERROR - Failed to execute job 156 for task es_task ('NoneType' object is not iterable; 1872)
[2025-04-30T10:27:09.522+0000] {local_task_job_runner.py:228} INFO - Task exited with return code 1
[2025-04-30T10:27:09.907+0000] {taskinstance.py:2778} INFO - 0 downstream tasks scheduled from follow-on schedule check
