[2025-04-30T10:26:26.147+0000] {taskinstance.py:1159} INFO - Dependencies all met for dep_context=non-requeueable deps ti=<TaskInstance: POC_orange_data2.es_task manual__2025-04-30T10:26:22.209765+00:00 [queued]>
[2025-04-30T10:26:26.210+0000] {taskinstance.py:1159} INFO - Dependencies all met for dep_context=requeueable deps ti=<TaskInstance: POC_orange_data2.es_task manual__2025-04-30T10:26:22.209765+00:00 [queued]>
[2025-04-30T10:26:26.211+0000] {taskinstance.py:1361} INFO - Starting attempt 1 of 1
[2025-04-30T10:26:26.356+0000] {taskinstance.py:1382} INFO - Executing <Task(PythonOperator): es_task> on 2025-04-30 10:26:22.209765+00:00
[2025-04-30T10:26:26.432+0000] {standard_task_runner.py:57} INFO - Started process 1536 to run task
[2025-04-30T10:26:26.506+0000] {standard_task_runner.py:84} INFO - Running: ['***', 'tasks', 'run', 'POC_orange_data2', 'es_task', 'manual__2025-04-30T10:26:22.209765+00:00', '--job-id', '154', '--raw', '--subdir', 'DAGS_FOLDER/pass_data.py', '--cfg-path', '/tmp/tmpry3y3zpk']
[2025-04-30T10:26:26.520+0000] {standard_task_runner.py:85} INFO - Job 154: Subtask es_task
[2025-04-30T10:26:28.207+0000] {task_command.py:416} INFO - Running <TaskInstance: POC_orange_data2.es_task manual__2025-04-30T10:26:22.209765+00:00 [running]> on host d9ec160e05b6
[2025-04-30T10:26:28.970+0000] {taskinstance.py:1662} INFO - Exporting env vars: AIRFLOW_CTX_DAG_OWNER='***' AIRFLOW_CTX_DAG_ID='POC_orange_data2' AIRFLOW_CTX_TASK_ID='es_task' AIRFLOW_CTX_EXECUTION_DATE='2025-04-30T10:26:22.209765+00:00' AIRFLOW_CTX_TRY_NUMBER='1' AIRFLOW_CTX_DAG_RUN_ID='manual__2025-04-30T10:26:22.209765+00:00'
[2025-04-30T10:26:29.052+0000] {logging_mixin.py:154} INFO - [INFO] Connecting to Elasticsearch...
[2025-04-30T10:26:29.063+0000] {taskinstance.py:1937} ERROR - Task failed with exception
Traceback (most recent call last):
  File "/home/airflow/.local/lib/python3.8/site-packages/airflow/operators/python.py", line 192, in execute
    return_value = self.execute_callable()
  File "/home/airflow/.local/lib/python3.8/site-packages/airflow/operators/python.py", line 209, in execute_callable
    return self.python_callable(*self.op_args, **self.op_kwargs)
  File "/opt/airflow/dags/pass_data.py", line 78, in save_to_es
    for idx, doc in enumerate(data):
TypeError: 'NoneType' object is not iterable
[2025-04-30T10:26:29.125+0000] {taskinstance.py:1400} INFO - Marking task as FAILED. dag_id=POC_orange_data2, task_id=es_task, execution_date=20250430T102622, start_date=20250430T102626, end_date=20250430T102629
[2025-04-30T10:26:29.226+0000] {standard_task_runner.py:104} ERROR - Failed to execute job 154 for task es_task ('NoneType' object is not iterable; 1536)
[2025-04-30T10:26:29.313+0000] {local_task_job_runner.py:228} INFO - Task exited with return code 1
[2025-04-30T10:26:30.226+0000] {taskinstance.py:2778} INFO - 0 downstream tasks scheduled from follow-on schedule check
