[2025-04-30T10:26:26.124+0000] {taskinstance.py:1159} INFO - Dependencies all met for dep_context=non-requeueable deps ti=<TaskInstance: POC_orange_data2.spark_task2 manual__2025-04-30T10:26:22.209765+00:00 [queued]>
[2025-04-30T10:26:26.206+0000] {taskinstance.py:1159} INFO - Dependencies all met for dep_context=requeueable deps ti=<TaskInstance: POC_orange_data2.spark_task2 manual__2025-04-30T10:26:22.209765+00:00 [queued]>
[2025-04-30T10:26:26.209+0000] {taskinstance.py:1361} INFO - Starting attempt 1 of 1
[2025-04-30T10:26:26.308+0000] {taskinstance.py:1382} INFO - Executing <Task(PythonOperator): spark_task2> on 2025-04-30 10:26:22.209765+00:00
[2025-04-30T10:26:26.360+0000] {standard_task_runner.py:57} INFO - Started process 1535 to run task
[2025-04-30T10:26:26.397+0000] {standard_task_runner.py:84} INFO - Running: ['***', 'tasks', 'run', 'POC_orange_data2', 'spark_task2', 'manual__2025-04-30T10:26:22.209765+00:00', '--job-id', '155', '--raw', '--subdir', 'DAGS_FOLDER/pass_data.py', '--cfg-path', '/tmp/tmp3rilo5iu']
[2025-04-30T10:26:26.412+0000] {standard_task_runner.py:85} INFO - Job 155: Subtask spark_task2
[2025-04-30T10:26:27.615+0000] {task_command.py:416} INFO - Running <TaskInstance: POC_orange_data2.spark_task2 manual__2025-04-30T10:26:22.209765+00:00 [running]> on host d9ec160e05b6
[2025-04-30T10:26:28.365+0000] {taskinstance.py:1662} INFO - Exporting env vars: AIRFLOW_CTX_DAG_OWNER='***' AIRFLOW_CTX_DAG_ID='POC_orange_data2' AIRFLOW_CTX_TASK_ID='spark_task2' AIRFLOW_CTX_EXECUTION_DATE='2025-04-30T10:26:22.209765+00:00' AIRFLOW_CTX_TRY_NUMBER='1' AIRFLOW_CTX_DAG_RUN_ID='manual__2025-04-30T10:26:22.209765+00:00'
[2025-04-30T10:26:28.374+0000] {logging_mixin.py:154} INFO - === Starting Spark CSV Processing DAG ===
[2025-04-30T10:27:05.196+0000] {logging_mixin.py:154} INFO - [INFO] Spark session successfully created.
[2025-04-30T10:27:05.201+0000] {logging_mixin.py:154} INFO - [INFO] Looking for CSV files in directory: /opt/***/data
[2025-04-30T10:27:05.206+0000] {logging_mixin.py:154} INFO - [INFO] 34 file(s) found for processing.
[2025-04-30T10:27:05.207+0000] {logging_mixin.py:154} INFO - [INFO] Processing file 1/34: /opt/***/data/generated_data_1.csv
[2025-04-30T10:27:13.594+0000] {local_task_job_runner.py:294} WARNING - State of this instance has been externally set to restarting. Terminating instance.
[2025-04-30T10:27:13.600+0000] {process_utils.py:131} INFO - Sending 15 to group 1535. PIDs of all processes in the group: [1537, 1535]
[2025-04-30T10:27:13.601+0000] {process_utils.py:86} INFO - Sending the signal 15 to group 1535
[2025-04-30T10:27:13.602+0000] {taskinstance.py:1632} ERROR - Received SIGTERM. Terminating subprocesses.
[2025-04-30T10:27:13.603+0000] {clientserver.py:538} INFO - Error while receiving.
Traceback (most recent call last):
  File "/home/airflow/.local/lib/python3.8/site-packages/py4j/clientserver.py", line 511, in send_command
    answer = smart_decode(self.stream.readline()[:-1])
  File "/usr/local/lib/python3.8/socket.py", line 669, in readinto
    return self._sock.recv_into(b)
  File "/home/airflow/.local/lib/python3.8/site-packages/airflow/models/taskinstance.py", line 1634, in signal_handler
    raise AirflowException("Task received SIGTERM signal")
airflow.exceptions.AirflowException: Task received SIGTERM signal
[2025-04-30T10:27:13.606+0000] {clientserver.py:543} INFO - Closing down clientserver connection
[2025-04-30T10:27:13.607+0000] {java_gateway.py:1055} ERROR - Exception while sending command.
Traceback (most recent call last):
  File "/home/airflow/.local/lib/python3.8/site-packages/py4j/clientserver.py", line 511, in send_command
    answer = smart_decode(self.stream.readline()[:-1])
  File "/usr/local/lib/python3.8/socket.py", line 669, in readinto
    return self._sock.recv_into(b)
  File "/home/airflow/.local/lib/python3.8/site-packages/airflow/models/taskinstance.py", line 1634, in signal_handler
    raise AirflowException("Task received SIGTERM signal")
airflow.exceptions.AirflowException: Task received SIGTERM signal

During handling of the above exception, another exception occurred:

Traceback (most recent call last):
  File "/home/airflow/.local/lib/python3.8/site-packages/py4j/java_gateway.py", line 1038, in send_command
    response = connection.send_command(command)
  File "/home/airflow/.local/lib/python3.8/site-packages/py4j/clientserver.py", line 539, in send_command
    raise Py4JNetworkError(
py4j.protocol.Py4JNetworkError: Error while sending or receiving
[2025-04-30T10:27:13.609+0000] {clientserver.py:543} INFO - Closing down clientserver connection
[2025-04-30T10:27:13.609+0000] {logging_mixin.py:154} INFO - [ERROR] Failed to process file /opt/***/data/generated_data_1.csv: An error occurred while calling o43.csv
[2025-04-30T10:27:13.610+0000] {logging_mixin.py:154} INFO - [INFO] Processing file 2/34: /opt/***/data/generated_data_10.csv
[2025-04-30T10:27:14.273+0000] {clientserver.py:538} INFO - Error while receiving.
Traceback (most recent call last):
  File "/home/airflow/.local/lib/python3.8/site-packages/py4j/clientserver.py", line 516, in send_command
    raise Py4JNetworkError("Answer from Java side is empty")
py4j.protocol.Py4JNetworkError: Answer from Java side is empty
[2025-04-30T10:27:14.274+0000] {clientserver.py:543} INFO - Closing down clientserver connection
[2025-04-30T10:27:14.274+0000] {clientserver.py:538} INFO - Error while receiving.
Traceback (most recent call last):
  File "/home/airflow/.local/lib/python3.8/site-packages/py4j/clientserver.py", line 511, in send_command
    answer = smart_decode(self.stream.readline()[:-1])
  File "/usr/local/lib/python3.8/socket.py", line 669, in readinto
    return self._sock.recv_into(b)
ConnectionResetError: [Errno 104] Connection reset by peer
[2025-04-30T10:27:14.275+0000] {clientserver.py:543} INFO - Closing down clientserver connection
[2025-04-30T10:27:14.276+0000] {java_gateway.py:1055} ERROR - Exception while sending command.
Traceback (most recent call last):
  File "/home/airflow/.local/lib/python3.8/site-packages/py4j/clientserver.py", line 511, in send_command
    answer = smart_decode(self.stream.readline()[:-1])
  File "/usr/local/lib/python3.8/socket.py", line 669, in readinto
    return self._sock.recv_into(b)
ConnectionResetError: [Errno 104] Connection reset by peer

During handling of the above exception, another exception occurred:

Traceback (most recent call last):
  File "/home/airflow/.local/lib/python3.8/site-packages/py4j/java_gateway.py", line 1038, in send_command
    response = connection.send_command(command)
  File "/home/airflow/.local/lib/python3.8/site-packages/py4j/clientserver.py", line 539, in send_command
    raise Py4JNetworkError(
py4j.protocol.Py4JNetworkError: Error while sending or receiving
[2025-04-30T10:27:14.276+0000] {clientserver.py:543} INFO - Closing down clientserver connection
[2025-04-30T10:27:14.277+0000] {java_gateway.py:1055} ERROR - Exception while sending command.
Traceback (most recent call last):
  File "/home/airflow/.local/lib/python3.8/site-packages/py4j/clientserver.py", line 516, in send_command
    raise Py4JNetworkError("Answer from Java side is empty")
py4j.protocol.Py4JNetworkError: Answer from Java side is empty

During handling of the above exception, another exception occurred:

Traceback (most recent call last):
  File "/home/airflow/.local/lib/python3.8/site-packages/py4j/java_gateway.py", line 1038, in send_command
    response = connection.send_command(command)
  File "/home/airflow/.local/lib/python3.8/site-packages/py4j/clientserver.py", line 539, in send_command
    raise Py4JNetworkError(
py4j.protocol.Py4JNetworkError: Error while sending or receiving
[2025-04-30T10:27:14.277+0000] {clientserver.py:543} INFO - Closing down clientserver connection
[2025-04-30T10:27:14.278+0000] {logging_mixin.py:154} INFO - [ERROR] Failed to process file /opt/***/data/generated_data_10.csv: An error occurred while calling o49.csv
[2025-04-30T10:27:14.278+0000] {logging_mixin.py:154} INFO - [INFO] Processing file 3/34: /opt/***/data/generated_data_11.csv
[2025-04-30T10:27:14.278+0000] {clientserver.py:543} INFO - Closing down clientserver connection
[2025-04-30T10:27:14.279+0000] {logging_mixin.py:154} INFO - [ERROR] Failed to process file /opt/***/data/generated_data_11.csv: [Errno 111] Connection refused
[2025-04-30T10:27:14.279+0000] {clientserver.py:543} INFO - Closing down clientserver connection
[2025-04-30T10:27:14.279+0000] {logging_mixin.py:154} INFO - [INFO] Processing file 4/34: /opt/***/data/generated_data_12.csv
[2025-04-30T10:27:14.279+0000] {clientserver.py:543} INFO - Closing down clientserver connection
[2025-04-30T10:27:14.279+0000] {logging_mixin.py:154} INFO - [ERROR] Failed to process file /opt/***/data/generated_data_12.csv: [Errno 111] Connection refused
[2025-04-30T10:27:14.280+0000] {clientserver.py:543} INFO - Closing down clientserver connection
[2025-04-30T10:27:14.280+0000] {logging_mixin.py:154} INFO - [INFO] Processing file 5/34: /opt/***/data/generated_data_13.csv
[2025-04-30T10:27:14.280+0000] {clientserver.py:543} INFO - Closing down clientserver connection
[2025-04-30T10:27:14.280+0000] {logging_mixin.py:154} INFO - [ERROR] Failed to process file /opt/***/data/generated_data_13.csv: [Errno 111] Connection refused
[2025-04-30T10:27:14.281+0000] {clientserver.py:543} INFO - Closing down clientserver connection
[2025-04-30T10:27:14.281+0000] {logging_mixin.py:154} INFO - [INFO] Processing file 6/34: /opt/***/data/generated_data_14.csv
[2025-04-30T10:27:14.281+0000] {clientserver.py:543} INFO - Closing down clientserver connection
[2025-04-30T10:27:14.281+0000] {logging_mixin.py:154} INFO - [ERROR] Failed to process file /opt/***/data/generated_data_14.csv: [Errno 111] Connection refused
[2025-04-30T10:27:14.281+0000] {clientserver.py:543} INFO - Closing down clientserver connection
[2025-04-30T10:27:14.282+0000] {logging_mixin.py:154} INFO - [INFO] Processing file 7/34: /opt/***/data/generated_data_15.csv
[2025-04-30T10:27:14.282+0000] {clientserver.py:543} INFO - Closing down clientserver connection
[2025-04-30T10:27:14.282+0000] {logging_mixin.py:154} INFO - [ERROR] Failed to process file /opt/***/data/generated_data_15.csv: [Errno 111] Connection refused
[2025-04-30T10:27:14.282+0000] {clientserver.py:543} INFO - Closing down clientserver connection
[2025-04-30T10:27:14.282+0000] {logging_mixin.py:154} INFO - [INFO] Processing file 8/34: /opt/***/data/generated_data_16.csv
[2025-04-30T10:27:14.283+0000] {clientserver.py:543} INFO - Closing down clientserver connection
[2025-04-30T10:27:14.283+0000] {logging_mixin.py:154} INFO - [ERROR] Failed to process file /opt/***/data/generated_data_16.csv: [Errno 111] Connection refused
[2025-04-30T10:27:14.283+0000] {clientserver.py:543} INFO - Closing down clientserver connection
[2025-04-30T10:27:14.283+0000] {logging_mixin.py:154} INFO - [INFO] Processing file 9/34: /opt/***/data/generated_data_17.csv
[2025-04-30T10:27:14.283+0000] {clientserver.py:543} INFO - Closing down clientserver connection
[2025-04-30T10:27:14.284+0000] {logging_mixin.py:154} INFO - [ERROR] Failed to process file /opt/***/data/generated_data_17.csv: [Errno 111] Connection refused
[2025-04-30T10:27:14.284+0000] {clientserver.py:543} INFO - Closing down clientserver connection
[2025-04-30T10:27:14.284+0000] {logging_mixin.py:154} INFO - [INFO] Processing file 10/34: /opt/***/data/generated_data_18.csv
[2025-04-30T10:27:14.284+0000] {clientserver.py:543} INFO - Closing down clientserver connection
[2025-04-30T10:27:14.285+0000] {logging_mixin.py:154} INFO - [ERROR] Failed to process file /opt/***/data/generated_data_18.csv: [Errno 111] Connection refused
[2025-04-30T10:27:14.285+0000] {clientserver.py:543} INFO - Closing down clientserver connection
[2025-04-30T10:27:14.285+0000] {logging_mixin.py:154} INFO - [INFO] Processing file 11/34: /opt/***/data/generated_data_19.csv
[2025-04-30T10:27:14.285+0000] {clientserver.py:543} INFO - Closing down clientserver connection
[2025-04-30T10:27:14.285+0000] {logging_mixin.py:154} INFO - [ERROR] Failed to process file /opt/***/data/generated_data_19.csv: [Errno 111] Connection refused
[2025-04-30T10:27:14.286+0000] {clientserver.py:543} INFO - Closing down clientserver connection
[2025-04-30T10:27:14.286+0000] {logging_mixin.py:154} INFO - [INFO] Processing file 12/34: /opt/***/data/generated_data_2.csv
[2025-04-30T10:27:14.286+0000] {clientserver.py:543} INFO - Closing down clientserver connection
[2025-04-30T10:27:14.286+0000] {logging_mixin.py:154} INFO - [ERROR] Failed to process file /opt/***/data/generated_data_2.csv: [Errno 111] Connection refused
[2025-04-30T10:27:14.286+0000] {clientserver.py:543} INFO - Closing down clientserver connection
[2025-04-30T10:27:14.287+0000] {logging_mixin.py:154} INFO - [INFO] Processing file 13/34: /opt/***/data/generated_data_20.csv
[2025-04-30T10:27:14.287+0000] {clientserver.py:543} INFO - Closing down clientserver connection
[2025-04-30T10:27:14.287+0000] {logging_mixin.py:154} INFO - [ERROR] Failed to process file /opt/***/data/generated_data_20.csv: [Errno 111] Connection refused
[2025-04-30T10:27:14.287+0000] {clientserver.py:543} INFO - Closing down clientserver connection
[2025-04-30T10:27:14.287+0000] {logging_mixin.py:154} INFO - [INFO] Processing file 14/34: /opt/***/data/generated_data_21.csv
[2025-04-30T10:27:14.288+0000] {clientserver.py:543} INFO - Closing down clientserver connection
[2025-04-30T10:27:14.288+0000] {logging_mixin.py:154} INFO - [ERROR] Failed to process file /opt/***/data/generated_data_21.csv: [Errno 111] Connection refused
[2025-04-30T10:27:14.288+0000] {clientserver.py:543} INFO - Closing down clientserver connection
[2025-04-30T10:27:14.288+0000] {logging_mixin.py:154} INFO - [INFO] Processing file 15/34: /opt/***/data/generated_data_22.csv
[2025-04-30T10:27:14.288+0000] {clientserver.py:543} INFO - Closing down clientserver connection
[2025-04-30T10:27:14.289+0000] {logging_mixin.py:154} INFO - [ERROR] Failed to process file /opt/***/data/generated_data_22.csv: [Errno 111] Connection refused
[2025-04-30T10:27:14.289+0000] {clientserver.py:543} INFO - Closing down clientserver connection
[2025-04-30T10:27:14.289+0000] {logging_mixin.py:154} INFO - [INFO] Processing file 16/34: /opt/***/data/generated_data_23.csv
[2025-04-30T10:27:14.289+0000] {clientserver.py:543} INFO - Closing down clientserver connection
[2025-04-30T10:27:14.289+0000] {logging_mixin.py:154} INFO - [ERROR] Failed to process file /opt/***/data/generated_data_23.csv: [Errno 111] Connection refused
[2025-04-30T10:27:14.290+0000] {clientserver.py:543} INFO - Closing down clientserver connection
[2025-04-30T10:27:14.290+0000] {logging_mixin.py:154} INFO - [INFO] Processing file 17/34: /opt/***/data/generated_data_24.csv
[2025-04-30T10:27:14.290+0000] {clientserver.py:543} INFO - Closing down clientserver connection
[2025-04-30T10:27:14.290+0000] {logging_mixin.py:154} INFO - [ERROR] Failed to process file /opt/***/data/generated_data_24.csv: [Errno 111] Connection refused
[2025-04-30T10:27:14.290+0000] {clientserver.py:543} INFO - Closing down clientserver connection
[2025-04-30T10:27:14.291+0000] {logging_mixin.py:154} INFO - [INFO] Processing file 18/34: /opt/***/data/generated_data_25.csv
[2025-04-30T10:27:14.291+0000] {clientserver.py:543} INFO - Closing down clientserver connection
[2025-04-30T10:27:14.291+0000] {logging_mixin.py:154} INFO - [ERROR] Failed to process file /opt/***/data/generated_data_25.csv: [Errno 111] Connection refused
[2025-04-30T10:27:14.291+0000] {clientserver.py:543} INFO - Closing down clientserver connection
[2025-04-30T10:27:14.291+0000] {logging_mixin.py:154} INFO - [INFO] Processing file 19/34: /opt/***/data/generated_data_26.csv
[2025-04-30T10:27:14.292+0000] {clientserver.py:543} INFO - Closing down clientserver connection
[2025-04-30T10:27:14.292+0000] {logging_mixin.py:154} INFO - [ERROR] Failed to process file /opt/***/data/generated_data_26.csv: [Errno 111] Connection refused
[2025-04-30T10:27:14.292+0000] {clientserver.py:543} INFO - Closing down clientserver connection
[2025-04-30T10:27:14.292+0000] {logging_mixin.py:154} INFO - [INFO] Processing file 20/34: /opt/***/data/generated_data_27.csv
[2025-04-30T10:27:14.292+0000] {clientserver.py:543} INFO - Closing down clientserver connection
[2025-04-30T10:27:14.293+0000] {logging_mixin.py:154} INFO - [ERROR] Failed to process file /opt/***/data/generated_data_27.csv: [Errno 111] Connection refused
[2025-04-30T10:27:14.293+0000] {clientserver.py:543} INFO - Closing down clientserver connection
[2025-04-30T10:27:14.293+0000] {logging_mixin.py:154} INFO - [INFO] Processing file 21/34: /opt/***/data/generated_data_28.csv
[2025-04-30T10:27:14.293+0000] {clientserver.py:543} INFO - Closing down clientserver connection
[2025-04-30T10:27:14.293+0000] {logging_mixin.py:154} INFO - [ERROR] Failed to process file /opt/***/data/generated_data_28.csv: [Errno 111] Connection refused
[2025-04-30T10:27:14.294+0000] {clientserver.py:543} INFO - Closing down clientserver connection
[2025-04-30T10:27:14.294+0000] {logging_mixin.py:154} INFO - [INFO] Processing file 22/34: /opt/***/data/generated_data_29.csv
[2025-04-30T10:27:14.294+0000] {clientserver.py:543} INFO - Closing down clientserver connection
[2025-04-30T10:27:14.294+0000] {logging_mixin.py:154} INFO - [ERROR] Failed to process file /opt/***/data/generated_data_29.csv: [Errno 111] Connection refused
[2025-04-30T10:27:14.295+0000] {clientserver.py:543} INFO - Closing down clientserver connection
[2025-04-30T10:27:14.295+0000] {logging_mixin.py:154} INFO - [INFO] Processing file 23/34: /opt/***/data/generated_data_3.csv
[2025-04-30T10:27:14.295+0000] {clientserver.py:543} INFO - Closing down clientserver connection
[2025-04-30T10:27:14.295+0000] {logging_mixin.py:154} INFO - [ERROR] Failed to process file /opt/***/data/generated_data_3.csv: [Errno 111] Connection refused
[2025-04-30T10:27:14.295+0000] {clientserver.py:543} INFO - Closing down clientserver connection
[2025-04-30T10:27:14.296+0000] {logging_mixin.py:154} INFO - [INFO] Processing file 24/34: /opt/***/data/generated_data_30.csv
[2025-04-30T10:27:14.296+0000] {clientserver.py:543} INFO - Closing down clientserver connection
[2025-04-30T10:27:14.296+0000] {logging_mixin.py:154} INFO - [ERROR] Failed to process file /opt/***/data/generated_data_30.csv: [Errno 111] Connection refused
[2025-04-30T10:27:14.296+0000] {clientserver.py:543} INFO - Closing down clientserver connection
[2025-04-30T10:27:14.297+0000] {logging_mixin.py:154} INFO - [INFO] Processing file 25/34: /opt/***/data/generated_data_31.csv
[2025-04-30T10:27:14.297+0000] {clientserver.py:543} INFO - Closing down clientserver connection
[2025-04-30T10:27:14.297+0000] {logging_mixin.py:154} INFO - [ERROR] Failed to process file /opt/***/data/generated_data_31.csv: [Errno 111] Connection refused
[2025-04-30T10:27:14.297+0000] {clientserver.py:543} INFO - Closing down clientserver connection
[2025-04-30T10:27:14.297+0000] {logging_mixin.py:154} INFO - [INFO] Processing file 26/34: /opt/***/data/generated_data_32.csv
[2025-04-30T10:27:14.298+0000] {clientserver.py:543} INFO - Closing down clientserver connection
[2025-04-30T10:27:14.298+0000] {logging_mixin.py:154} INFO - [ERROR] Failed to process file /opt/***/data/generated_data_32.csv: [Errno 111] Connection refused
[2025-04-30T10:27:14.298+0000] {clientserver.py:543} INFO - Closing down clientserver connection
[2025-04-30T10:27:14.298+0000] {logging_mixin.py:154} INFO - [INFO] Processing file 27/34: /opt/***/data/generated_data_33.csv
[2025-04-30T10:27:14.298+0000] {clientserver.py:543} INFO - Closing down clientserver connection
[2025-04-30T10:27:14.299+0000] {logging_mixin.py:154} INFO - [ERROR] Failed to process file /opt/***/data/generated_data_33.csv: [Errno 111] Connection refused
[2025-04-30T10:27:14.299+0000] {clientserver.py:543} INFO - Closing down clientserver connection
[2025-04-30T10:27:14.299+0000] {logging_mixin.py:154} INFO - [INFO] Processing file 28/34: /opt/***/data/generated_data_34.csv
[2025-04-30T10:27:14.299+0000] {clientserver.py:543} INFO - Closing down clientserver connection
[2025-04-30T10:27:14.300+0000] {logging_mixin.py:154} INFO - [ERROR] Failed to process file /opt/***/data/generated_data_34.csv: [Errno 111] Connection refused
[2025-04-30T10:27:14.300+0000] {clientserver.py:543} INFO - Closing down clientserver connection
[2025-04-30T10:27:14.300+0000] {logging_mixin.py:154} INFO - [INFO] Processing file 29/34: /opt/***/data/generated_data_4.csv
[2025-04-30T10:27:14.300+0000] {clientserver.py:543} INFO - Closing down clientserver connection
[2025-04-30T10:27:14.300+0000] {logging_mixin.py:154} INFO - [ERROR] Failed to process file /opt/***/data/generated_data_4.csv: [Errno 111] Connection refused
[2025-04-30T10:27:14.301+0000] {clientserver.py:543} INFO - Closing down clientserver connection
[2025-04-30T10:27:14.301+0000] {logging_mixin.py:154} INFO - [INFO] Processing file 30/34: /opt/***/data/generated_data_5.csv
[2025-04-30T10:27:14.301+0000] {clientserver.py:543} INFO - Closing down clientserver connection
[2025-04-30T10:27:14.301+0000] {logging_mixin.py:154} INFO - [ERROR] Failed to process file /opt/***/data/generated_data_5.csv: [Errno 111] Connection refused
[2025-04-30T10:27:14.301+0000] {clientserver.py:543} INFO - Closing down clientserver connection
[2025-04-30T10:27:14.302+0000] {logging_mixin.py:154} INFO - [INFO] Processing file 31/34: /opt/***/data/generated_data_6.csv
[2025-04-30T10:27:14.302+0000] {clientserver.py:543} INFO - Closing down clientserver connection
[2025-04-30T10:27:14.302+0000] {logging_mixin.py:154} INFO - [ERROR] Failed to process file /opt/***/data/generated_data_6.csv: [Errno 111] Connection refused
[2025-04-30T10:27:14.302+0000] {clientserver.py:543} INFO - Closing down clientserver connection
[2025-04-30T10:27:14.302+0000] {logging_mixin.py:154} INFO - [INFO] Processing file 32/34: /opt/***/data/generated_data_7.csv
[2025-04-30T10:27:14.303+0000] {clientserver.py:543} INFO - Closing down clientserver connection
[2025-04-30T10:27:14.303+0000] {logging_mixin.py:154} INFO - [ERROR] Failed to process file /opt/***/data/generated_data_7.csv: [Errno 111] Connection refused
[2025-04-30T10:27:14.303+0000] {clientserver.py:543} INFO - Closing down clientserver connection
[2025-04-30T10:27:14.303+0000] {logging_mixin.py:154} INFO - [INFO] Processing file 33/34: /opt/***/data/generated_data_8.csv
[2025-04-30T10:27:14.303+0000] {clientserver.py:543} INFO - Closing down clientserver connection
[2025-04-30T10:27:14.304+0000] {logging_mixin.py:154} INFO - [ERROR] Failed to process file /opt/***/data/generated_data_8.csv: [Errno 111] Connection refused
[2025-04-30T10:27:14.304+0000] {clientserver.py:543} INFO - Closing down clientserver connection
[2025-04-30T10:27:14.304+0000] {logging_mixin.py:154} INFO - [INFO] Processing file 34/34: /opt/***/data/generated_data_9.csv
[2025-04-30T10:27:14.304+0000] {clientserver.py:543} INFO - Closing down clientserver connection
[2025-04-30T10:27:14.304+0000] {logging_mixin.py:154} INFO - [ERROR] Failed to process file /opt/***/data/generated_data_9.csv: [Errno 111] Connection refused
[2025-04-30T10:27:14.305+0000] {clientserver.py:543} INFO - Closing down clientserver connection
[2025-04-30T10:27:14.305+0000] {logging_mixin.py:154} INFO - [INFO] Stopping Spark session.
[2025-04-30T10:27:14.305+0000] {clientserver.py:543} INFO - Closing down clientserver connection
[2025-04-30T10:27:14.305+0000] {logging_mixin.py:154} INFO - [FATAL] Spark processing failed: [Errno 111] Connection refused
[2025-04-30T10:27:14.305+0000] {clientserver.py:543} INFO - Closing down clientserver connection
[2025-04-30T10:27:14.306+0000] {python.py:194} INFO - Done. Returned value was: Failed: [Errno 111] Connection refused
[2025-04-30T10:27:14.353+0000] {taskinstance.py:1400} INFO - Marking task as SUCCESS. dag_id=POC_orange_data2, task_id=spark_task2, execution_date=20250430T102622, start_date=20250430T102626, end_date=20250430T102714
[2025-04-30T10:27:14.429+0000] {process_utils.py:79} INFO - Process psutil.Process(pid=1537, status='terminated', started='10:26:28') (1537) terminated with exit code None
[2025-04-30T10:27:14.430+0000] {process_utils.py:79} INFO - Process psutil.Process(pid=1535, status='terminated', exitcode=0, started='10:26:26') (1535) terminated with exit code 0
