[2025-05-13T13:12:10.808+0000] {taskinstance.py:1159} INFO - Dependencies all met for dep_context=non-requeueable deps ti=<TaskInstance: POC_orange_data2.es_task scheduled__2025-05-12T00:00:00+00:00 [queued]>
[2025-05-13T13:12:10.835+0000] {taskinstance.py:1159} INFO - Dependencies all met for dep_context=requeueable deps ti=<TaskInstance: POC_orange_data2.es_task scheduled__2025-05-12T00:00:00+00:00 [queued]>
[2025-05-13T13:12:10.836+0000] {taskinstance.py:1361} INFO - Starting attempt 1 of 1
[2025-05-13T13:12:10.890+0000] {taskinstance.py:1382} INFO - Executing <Task(PythonOperator): es_task> on 2025-05-12 00:00:00+00:00
[2025-05-13T13:12:10.902+0000] {standard_task_runner.py:57} INFO - Started process 199 to run task
[2025-05-13T13:12:10.914+0000] {standard_task_runner.py:84} INFO - Running: ['***', 'tasks', 'run', 'POC_orange_data2', 'es_task', 'scheduled__2025-05-12T00:00:00+00:00', '--job-id', '169', '--raw', '--subdir', 'DAGS_FOLDER/pass_data.py', '--cfg-path', '/tmp/tmpocrq5y1q']
[2025-05-13T13:12:10.922+0000] {standard_task_runner.py:85} INFO - Job 169: Subtask es_task
[2025-05-13T13:12:11.067+0000] {task_command.py:416} INFO - Running <TaskInstance: POC_orange_data2.es_task scheduled__2025-05-12T00:00:00+00:00 [running]> on host 8fab0bc9647a
[2025-05-13T13:12:12.113+0000] {taskinstance.py:1662} INFO - Exporting env vars: AIRFLOW_CTX_DAG_OWNER='***' AIRFLOW_CTX_DAG_ID='POC_orange_data2' AIRFLOW_CTX_TASK_ID='es_task' AIRFLOW_CTX_EXECUTION_DATE='2025-05-12T00:00:00+00:00' AIRFLOW_CTX_TRY_NUMBER='1' AIRFLOW_CTX_DAG_RUN_ID='scheduled__2025-05-12T00:00:00+00:00'
[2025-05-13T13:12:12.151+0000] {logging_mixin.py:154} INFO - [INFO] Connecting to Elasticsearch...
[2025-05-13T13:12:12.157+0000] {taskinstance.py:1937} ERROR - Task failed with exception
Traceback (most recent call last):
  File "/home/airflow/.local/lib/python3.8/site-packages/airflow/operators/python.py", line 192, in execute
    return_value = self.execute_callable()
  File "/home/airflow/.local/lib/python3.8/site-packages/airflow/operators/python.py", line 209, in execute_callable
    return self.python_callable(*self.op_args, **self.op_kwargs)
  File "/opt/airflow/dags/pass_data.py", line 78, in save_to_es
    for idx, doc in enumerate(data):
TypeError: 'NoneType' object is not iterable
[2025-05-13T13:12:12.186+0000] {taskinstance.py:1400} INFO - Marking task as FAILED. dag_id=POC_orange_data2, task_id=es_task, execution_date=20250512T000000, start_date=20250513T131210, end_date=20250513T131212
[2025-05-13T13:12:12.230+0000] {standard_task_runner.py:104} ERROR - Failed to execute job 169 for task es_task ('NoneType' object is not iterable; 199)
[2025-05-13T13:12:12.263+0000] {local_task_job_runner.py:228} INFO - Task exited with return code 1
[2025-05-13T13:12:12.326+0000] {taskinstance.py:2778} INFO - 0 downstream tasks scheduled from follow-on schedule check
